Workbook

Sheet MJ 5.0 - ND Task list
B1: Level | C1: Phân loại công việc | D1: Đầu việc | E1: PIC | F1: Quantity | G1: Capacity/unit | H1: Task capacity | I1: Start date | J1: End date | K1: Status | L1: Note | M1: Tháng 6 | Q1: Tháng 7 | U1: Tháng 8
A2: Luồng học chính
A3: =row()-2 -> 1 | B3: Level 0 | C3: Data | D3: Pair lại data 2 topics = 8 từ | E3: Duyên | G3: 1 | K3: Done
A4: =row()-2 -> 2 | B4: Level 0 | C4: Data | D4: Check data của Monkey Kindy, MS để match với data M.ABC -> sắp xếp lại thứ tự | E4: Duyên | K4: Done
A5: =row()-2 -> 3 | B5: Level 0 | C5: Data | D5: Config data 41 units | E5: Duyên | J5: 28/6 | K5: Done
A6: =row()-2 -> 4 | B6: Level 0 | C6: Game | D6: Nghiên cứu + chốt game dùng để thể hiện truyện MS/ video Kindy | E6: Duyên | K6: Done
A7: =row()-2 -> 5 | B7: Level 0 | C7: Game | D7: A Dũng đánh giá lại sửa file gaf truyện anim sang spine để đưa lên game | E7: Media | K7: Cancelled
A8: 6 | B8: Level 0 | D8: Dev 8 games | E8: KT | K8: Doing
A9: =row()-2 -> 7 | B9: Level 1-5 | C9: Data | D9: Tổng hợp data audio truyện + act MTC Story | E9: Thiên Anh | K9: Done
A10: =row()-2 -> 8 | B10: Level 1-5 | D10: Config data 3 unit test | E10: Thiên Anh | K10: Done
A11: =row()-2 -> 9 | B11: Level 1-5 | D11: Test data 3 unit test | E11: Thiên Anh | K11: Done
A12: =row()-2 -> 10 | B12: Level 1-5 | D12: Test 34 game done dev | E12: Thiên Anh | J12: 45467 | K12: Done
A13: =row()-2 -> 11 | B13: Level 1-5 | D13: Nghiệm thu các game có CR (sau TNNB) | E13: Thiên Anh | K13: NYS
A14: =row()-2 -> 12 | B14: Level 1-5 | D14: Test full luồng 3 unit | E14: Thiên Anh | J14: 45468 | K14: Done
A15: =row()-2 -> 13 | B15: Level 1-5 | D15: Hoàn thiện data full 60 unit | E15: Thiên Anh | K15: Done
A16: =row()-2 -> 14 | B16: Level 1-5 | C16: Game | D16: Config data full truyện + hội thoại | E16: KT | K16: Done
A17: =row()-2 -> 15 | B17: Level 1-5 | D17: Test + sửa lại full data truyện | E17: Thiên Anh | J17: 45471 | K17: Done
A18: =row()-2 -> 16 | B18: Level 1-5 | D18: Test + sửa lại full data hội thoại | E18: Thiên Anh | J18: 45471 | K18: Done
A19: =row()-2 -> 17 | B19: Level 1-5 | D19: Config full data 60 unit phase 1 | E19: KT | K19: Done
A20: =row()-2 -> 18 | B20: Level 1-5 | D20: Config full data 20 unit phase 1 | E20: KT | J20: 45478 | K20: Doing
A21: =row()-2 -> 19 | B21: Level 1-5 | D21: Config full data 20 unit phase 2 | E21: KT | K21: Delayed
A22: =row()-2 -> 20 | B22: Level 1-5 | D22: Test full bài học 80 unit phase 1 | E22: Team ND | K22: Doing
A23: =row()-2 -> 21 | B23: Level 1-5 | D23: Test full bài học 20 unit phase 2 | E23: Team ND | K23: Delayed
A24: =row()-2 -> 22 | B24: Level 1-5 | D24: Config 25 video interactive phase 1 | E24: Thiên Anh | K24: Done
A25: =row()-2 -> 23 | B25: Level 1-5 | D25: Config 3 video interactive phase 2 | E25: Thiên Anh | K25: NYS
A26: =row()-2 -> 24 | B26: Level 1-5 | D26: Test 26 video interactive phase 1 | E26: Thiên Anh | K26: Done
A27: =row()-2 -> 25 | B27: Level 1-5 | C27: Data | D27: Bổ sung video U61-70 | E27: Media | J27: 45467 | K27: Done
A28: =row()-2 -> 26 | B28: Level 1-5 | D28: Bổ sung video U81-90 | E28: Media | J28: 45495 | K28: NYS
A29: =row()-2 -> 27 | B29: Level 1-5 | D29: Bổ sung video U71-80 | E29: Media | K29: NYS
A30: =row()-2 -> 28 | B30: Level 1-5 | D30: Bổ sung video U91-100 | E30: Media | K30: NYS
A31: =row()-2 -> 29 | B31: Level 1-5 | D31: Duyệt video U61-70 | E31: Thiên Anh | J31: 45467 | K31: Done
A32: =row()-2 -> 30 | B32: Level 1-5 | D32: Duyệt video U81-90 | E32: Thiên Anh | J32: 45495 | K32: NYS
A33: =row()-2 -> 31 | B33: Level 1-5 | D33: Duyệt video U71-80 | E33: Thiên Anh | K33: NYS
A34: =row()-2 -> 32 | B34: Level 1-5 | D34: Duyệt video U91-100 | E34: Thiên Anh | K34: NYS
A35: =row()-2 -> 33 | B35: Level 1-5 | D35: Gắn link audio blending sounds | E35: Thiên Anh | K35: Done
A36: =row()-2 -> 34 | B36: Level 1-5 | D36: Gắn link audio letter name | E36: Thiên Anh | K36: Done
A37: =row()-2 -> 35 | B37: Level 1-5 | D37: Thu âm + gắn link audio speaking competition | E37: Thiên Anh | K37: Done
A38: =row()-2 -> 36 | B38: Level 1-5 | C38: Data | D38: Thiết kế ảnh game Điền thế sentence | E38: CTV | K38: Done
A39: =row()-2 -> 37 | B39: Level 1-5 | D39: Thiết kế ảnh game Jumbled pages | E39: CTV | K39: Done
A40: =row()-2 -> 38 | B40: Level 1-5 | C40: Data | D40: Bổ sung CHTT act Jumbled pages | E40: Nguyệt | K40: Done
...

Sheet MC - Khung CT + checkpoints
A1: Mục tiêu | C1: 1 week challenge
A2: 1. Mục tiêu: - Cung cấp thêm giá trị > tăng tỉ lệ mua 01 - Kết nối với bố mẹ - Cross sale - Upsale 2. Cách triển khai: - Đưa giáo trình học + checkpoints - Học theo lộ trình + GV chấm điểm, comment - Testing nếu có (có thể làm in app) 3. Nền tảng: - Monkey Class 4. PH nhận được gì: - Thời khóa biểu - Hiểu về chương trình học - Report tuần - Report kì | C2: Nội dung | F2: Cách làm | I2: Các dạng challenge
C3: Học 3-4 bài | F3: Quay video cô giáo giới thiệu challenge (giao vào đầu tuần) | I3: - Học 3-4 bài/học 10 phút
C4: Học 1 bài cross course (chỉ mở cho các bạn tham gia MC + theo tuần) | F4: Push challenge board vào launch app, hoàn thành bài học (MJ5 hoặc cross course) | I4: - Học lesson M-ABC/MSP/MS
C5: 1 challenge activity | F5: Bài extra trên mj app/quay phim nộp lên MC | I5: - Đọc truyện MS + hoàn thành CHTT
I6: - Thu âm truyện MS
I7: - Quay video con học/chơi (hát theo video/thu âm/video call)
I8: - Quay video ba mẹ hỏi - con trả lời theo chủ đề
I9: - Quay video ba mẹ show từ - con nói/mô tả lại từ đó
I10: - Quay video con mô tả 1 bức tranh,...
I11: - Quay video con thuyết trình về 1 chủ đề
I12: - Giao worksheet -> bố mẹ in ra cho con làm, chụp lại nộp
I13: - Lồng tiếng truyện
I14: - Giao 1 bài & quay phim lại con đọc
C15: Lv 0: học 1 unit trong 1 tuần => 41 tuần xong | I15: - Làm poster/mind map/mô hình/project, chụp lại (có thể thêm mô tả)
C16: Lv 1-5: học 1 unit trong 2 tuần -> 40 tuần sẽ xong 1 level | I16: - Giao 1 chủ đề, con viết về chủ đề đó
C18: TKB chi tiết | D18: Tuần 1 | E18: Tuần 2 | F18: Tuần 3 | G18: Tuần 4 | H18: Tuần 5 | I18: Tuần 6 | J18: Tuần 7 | K18: Tuần 8 | L18: Tuần 9 | M18: Tuần 10 | N18: Tuần 11 | O18: Tuần 12 | P18: Tuần 13 | Q18: Tuần 14 | R18: Tuần 15 | S18: Tuần 16 | T18: Tuần 17 | U18: Tuần 18 | V18: Tuần 19 | W18: Tuần 20 | X18: Tuần 21 | Y18: Tuần 22 | Z18: Tuần 23 | AA18: Tuần 24 | AB18: Tuần 25 | AC18: Tuần 26 | AD18: Tuần 27 | AE18: Tuần 28 | AF18: Tuần 29 | AG18: Tuần 30 | AH18: Tuần 31 | AI18: Tuần 32 | AJ18: Tuần 33 | AK18: Tuần 34 | AL18: Tuần 35 | AM18: Tuần 36 | AN18: Tuần 37 | AO18: Tuần 38 | AP18: Tuần 39 | AQ18: Tuần 40
C19: Level 0 | D19: - Hoàn thiện 5 bài học (Unit 1) - Quay video con học/chơi/ hát theo video | E19: - Hoàn thiện 5 bài học (Unit 2) - Quay video ba mẹ hỏi - con trả lời theo chủ đề | F19: - Hoàn thiện 5 bài học (Unit 3) - Chụp ảnh/ quay con tô màu worksheet | G19: - Hoàn thiện 5 bài học (Unit 4) - | H19: - Hoàn thiện 5 bài học (Unit 5) - Quay video con học/chơi/ hát theo video | I19: - Hoàn thiện 5 bài học (Unit 6) - Quay video ba mẹ hỏi - con trả lời theo chủ đề | J19: - Hoàn thiện 5 bài học (Unit 7) - Chụp ảnh/ quay con tô màu worksheet | K19: - Hoàn thiện 5 bài học (Unit 8) -
C20: Level 1 | D20: - Hoàn thiện 3 bài học - Học 1 lesson M-ABC - Quay lại video con hát theo bài hát trong Lesson 3 | E20: - Hoàn thiện 4 bài học - Đọc đúng hết các từ trong act thu âm | F20: - Hoàn thiện 3 bài học - Học 1 lesson M-ABC - Quay lại video con giới thiệu bản thân | G20: - Hoàn thiện 4 bài học - Quay video con thu âm hội thoại cuối Lesson 14 | H20: - Hoàn thiện 3 bài học - Đọc 1 truyện MS và hoàn thành hết CHTT | I20: - Hoàn thiện 4 bài học - Quay video ba mẹ show từ - con nói/mô tả lại từ đó | J20: - Hoàn thiện 3 bài học - Đọc 1 truyện MS hoàn thành hết CHTT | K20: - Hoàn thiện 4 bài học - Quay video con thu âm hội thoại cuối Lesson 28
C21: Level 2 | D21: - Hoàn thiện 3 bài học - Đọc 1 truyện MS và hoàn thành hết CHTT | E21: - Hoàn thiện 4 bài học - Quay video con thu âm hội thoại cuối Lesson 7 | F21: - Hoàn thiện 3 bài học - Đọc 1 truyện MS - Quay video con thu âm 1 truyện MS | G21: - Hoàn thiện 4 bài học - Chụp ảnh con vẽ hình 1 chiếc áo đc dạy trong bài | H21: - Hoàn thiện 3 bài học - Quay lại video con đọc chữ cái "y" và viết chữ y ra giấy | I21: - Hoàn thiện 4 bài học - Quay video ba mẹ hỏi - con trả lời theo chủ đề | J21: - Hoàn thiện 3 bài học - Học 2 lesson MSP | K21: - Hoàn thiện 4 bài học - Quay video con chơi Lesson 28
C22: Level 3 | D22: - Hoàn thiện 3 bài học - Quay video con đánh vần các từ ở lesson 2 | E22: - Hoàn thiện 4 bài học - Quay video ba mẹ hỏi - con trả lời theo chủ đề | F22: - Hoàn thiện 3 bài học - Học 2 bài MSP | G22: - Hoàn thành 4 bài học - Quay video con chơi 1 video call MSP | H22: - Hoàn thiện 3 bài học - Đọc 1 truyện MS - Lồng tiếng 1 truyện MS | I22: - Hoàn thiện 4 bài học - Quay video con chơi Lesson 21 | J22: - Hoàn thiện 3 bài học - Quay video con viết chữ ff | K22: - Hoàn thiện 4 bài học - Quay video ba mẹ hỏi, con trả lời theo đoạn hội thoại trong bài
C23: Level 4 | D23: - Hoàn thiện 3 bài học - Ba mẹ hỏi con tìm các từ có âm fl -> quay video con nói | E23: - Hoàn thiện 4 bài học - Quay video con nói về chủ đề Camping | F23: - Hoàn thiện 3 bài học - Quay lại video con phát âm /sl/ và viết chữ "sl" ra giấy | G23: - Hoàn thiện 4 bài học - Quay video con thu âm hội thoại cuối Lesson 14 | H23: - Hoàn thiện 3 bài học - Học 2 bài MSP | I23: - Hoàn thiện 4 bài học - Quay video con nói về chủ đề Painting | J23: - Hoàn thiện 3 bài học - Đọc 1 truyện MS - Lồng tiếng 1 truyện MS | K23: - Hoàn thành 4 bài học - Quay video con chơi 1 video call MSP
C24: Level 5 | D24: - Hoàn thiện 3 bài học - Đọc 1 truyện MS và hoàn thành hết CHTT | E24: - Hoàn thiện 4 bài học - Quay video con mô tả 1 bức tranh | F24: - Hoàn thiện 3 bài học - Quay lại video con hát theo video ở cuối lesson 10 | G24: - Hoàn thiện 4 bài học - Quay video con chơi Lesson 14 | H24: - Hoàn thiện 3 bài học - Quay video con thuyết trình về môn thể thao con thích | I24: - Hoàn thiện 3 bài học - Đọc 1 truyện MS - Lồng tiếng 1 truyện MS | J24: - Hoàn thiện 3 bài học - Đọc 1 truyện MS - Quay video con lồng tiếng 1 truyện MS | K24: - Hoàn thành 4 bài học - Quay video con chơi 1 video call MSP

Sheet MJ 5.0_Level 0_ Tổng quan
A1: Tên sản phẩm | B1: MJ 5.0_Level 0
A2: Định nghĩa | B2: Khóa học dạy tiếng Anh với định hướng tập trung từ vựng, áp dụng các phương pháp Giáo dục sớm
A3: Đối tượng sử dụng | B3: Trẻ 0-3 tuổi
A4: Phương pháp | B4: 1. Chụp hình nguyên từ 2. Tráo thẻ nhanh - Glenn Doman 3. Học thông qua trò chơi
A5: Hệ thống nội dung | B5: Nội dung học: tập trung học từ vựng với 2 loại từ: - Từ vựng chủ đề - Từ sight word
A6: Cấp độ bài học | B6: 3 cấp độ: Cơ bản - Trung bình - Nâng cao
A7: Luồng bài học | B7: Luồng bài học
A8: Games | B8: List game
A9: Input - Output | B9: - Input: chưa biết gì về tiếng Anh, độ tuổi 0-3 - Output: Nhận biết các từ vựng ở các topic rất phổ biến (Animals, Shapes, Actions, Fruits, Food, Toys), là tiền đề để học khóa học M.Go

Sheet MJ 5.0_Level 1-5_Tổng quan
A1: Tên sản phẩm | B1: Monkey Go
A2: Tổng quan | B2: - Khóa học giúp trẻ phát triển 4 kỹ năng: Nghe - Nói - Đọc - Viết - Dành cho trẻ độ tuổi 3-8 (ideally là chưa biết nhiều về tiếng Anh/ ít tiếp xúc với tiếng Anh)
A3: 2. Nhu cầu của bố mẹ | B3: Mục đích khi ba mẹ cho con học apps: - Học từ vựng - Học phát âm - Học giao tiếp - Thi chứng chỉ Hướng nội dung + tính năng ba mẹ mong muốn trên app: - Kết hợp games + interactive learnings - Personalized learning (child's progress and performance) - Multimedia and Visual Learning - Speech Recognition and Pronunciation Improvement - Parental Involvement and Progress Tracking - AI-Powered Learning Assistants (chatbots and virtual assistants) - Customizable Learning Paths
A4: 3. Lỗ hổng của app MJ hiện tại | B4: - MABC: tập trung dạy từ vựng cho trẻ 0-6, focus chính vào độ tuổi 0-3, hình ảnh + phương pháp chủ yếu cho 0-3 nhiều hơn - Khóa Monkey Stories: tập trung dạy đọc hiểu thông qua truyện cho độ tuổi 3-11, phát triển từ app MS cũ, nhưng đã bỏ đi phần bài học phonics (gồm 243 bài cho tổng 3 level) - Khóa Monkey Speak: tập trung phát triển kỹ năng nói cho độ tuổi 3-11 - Chưa có khóa dạy 4 kỹ năng + bổ sung phần phonics bị bỏ đi khi chuyển từ app MS lên khóa MS - Chưa có khóa học dùng các nội dung xuất hiện trên Media để dạy
A5: Tâm lý học của trẻ 3-8 Reference | B5: - Thích dùng các phương tiện Media - Bị hấp dẫn bởi các nội dung như video, games - Thích học thông qua các học liệu đa dạng, có kèm theo các nội dung giải trí: truyện, video, songs - Học được từ vựng qua các ngữ cảnh thực tế Các act nên sử dụng: - <4t: phonics, tracing, coloring, videos, songs - 4-6t: videos, songs, stories, repeat - 7-8t: videos, songs, stories, word search,... | C5: Trẻ mẫu giáo bé (3-4 tuổi) - Tư duy trực quan hành động: trẻ tiếp xúc và khám phá thế giới chủ yếu qua các giác quan. Trẻ sẽ sử dụng tư duy trực quan để liên kết những thông tin con thu thập và cố gắng để hiểu thế giới xung quanh - Bắt chước và thử nghiệm: khả năng bắt chước hành vi từ người lớn. Dù có thể chưa đạt đến mức sáng tạo cao, trẻ vẫn thể hiện sự tò mò và ham học hỏi, thích thử nghiệm và tìm hiểu. - Phân loại thông tin: Trẻ bắt đầu có khả năng phân loại các đồ vật theo những đặc điểm cơ bản như màu sắc, kích thước và hình dạng, nhưng chỉ ở mức độ cơ bản. Trẻ mẫu giáo nhỏ (4-5 tuổi) - Tư duy trực quan hình ảnh phát triển mạnh: trẻ có khả năng tưởng tượng ra các sự vật, hiện tượng mà trước đây con chưa từng thấy hoặc trải qua. Trẻ có thể tạo ra những câu chuyện riêng biệt, tưởng tượng ra các trò chơi, và thậm chí là tạo ra những bức tranh phong phú từ trí tưởng tượng của mình. - Tư duy từ ngữ - logic bắt đầu xuất hiện: trẻ có thể sử dụng từ ngữ để diễn đạt suy nghĩ, cảm xúc và giải quyết các vấn đề một cách lôgic hơn. Trẻ cũng bắt đầu đặt ra các câu hỏi tò mò, phân tích nguyên nhân và kết quả - Khả năng giải quyết vấn đề phức tạp hơn: con có thể tham gia vào các trò chơi xếp hình, lắp ráp và thử thách tư duy khác mà trước đây không thể thực hiện được một cách chính xác. Trẻ mẫu giáo lớn (5-6 tuổi), bước ngoặt quan trọng trong sự mở rộng tư duy logic và từ ngữ của trẻ - Tư duy từ ngữ - lôgic phát triển mạnh: trẻ bắt đầu sử dụng từ ngữ như một công cụ mạnh mẽ để diễn đạt suy nghĩ và trải nghiệm của mình. Trong đó, con không chỉ diễn đạt được ý nghĩa bề nổi, mà còn có khả năng phân tích và đánh giá thông tin một cách lôgic hơn. - Khả năng phân loại và tổ chức thông tin: Trẻ ở giai đoạn này có khả năng phân loại, so sánh và tổ chức thông tin một cách chi tiết và có hệ thống. Trẻ có thể nhận diện mối liên hệ giữa các sự vật và hiện tượng, giúp con hiểu rõ hơn về thế giới xung quanh. - Khả năng tư duy trừu tượng và sáng tạo: Trẻ bắt đầu phát triển khả năng tư duy trừu tượng, điều này giúp con hiểu được ý nghĩa sâu xa từ các khái niệm như tình yêu, tình bạn hay công bằng. Hơn nữa, sự sáng tạo của trẻ cũng được nâng cao, và con thể hiện điều này qua các hoạt động nghệ thuật như vẽ, viết hay sáng tác. - Tư duy độc lập và phê phán: Trẻ mẫu giáo lớn có xu hướng hình thành quan điểm và ý kiến riêng, thể hiện sự độc lập trong tư duy. Lúc này, con cũng bắt đầu biểu lộ khả năng phê phán, đặt ra câu hỏi và thách thức những thông tin được truyền đạt. | D5: Average Attention Span 3 years old: 6-8 minutes 4 years old: 8-12 minutes 5-6 years old: 12-18 minutes 7–8 years old: 16-24 minutes | E5: 6 weeks vowels sounds 6 months consonants 1,5 years single words + meaning 2 years single words together + simple sentences 5 years rhyme words 5-6 years blending 6 years story 8 years write simple story
A6: Lý do cần khóa Monkey Go | B6: - Đáp ứng nhu cầu làm quen với tiếng Anh giao tiếp và học 4 kỹ năng ở trẻ nhỏ - Bổ sung vào hệ sinh thái sản phẩm của siêu app: + 0-3: M.ABC + 3-8: M.Go - Bổ sung phần Phonics bị thiếu khi KH chuyển từ app MS sang khóa MS trong siêu app, cũng bổ trợ cho phương pháp học phonics đang được áp dụng gần đây trong bộ sgk tiểu học) - Bổ sung phương pháp học mới cho siêu app: học thông qua media-based, material-based learning - Là cầu nối để hook bán các khóa offline: K5 (chương trình bổ trợ kiến thức trên lớp), Monkey Tutoring (5-10 tuổi, học giao tiếp)
A7: Hệ thống nội dung | B7: - Gồm 5 level (mỗi level 20 unit) với độ khó tăng dần. Flow bài học cố định, tuy nhiên có thể tự do chọn level - Dạy phonics, vocab, sentence, dialog, story Bảng data tổng
A8: Các phương pháp sẽ được ứng dụng trong Monkey Go | B8: Phương pháp
A9: Cách dạy các kỹ năng Nghe - Nói - Đọc - Viết
A10: 9. Selling points của khóa học | B10: - Hệ thống học liệu đa dạng, hiện đại: từ vựng (phonics, từ topics), câu, sight words, truyện tranh, video, games - Game hiện đại, có cốt truyện - Kho truyện được viết riêng, minh họa hiện đại, nội dung hấp dẫn - Nội dung đi theo phương pháp phonics được công nhận trên thế giới (Jolly Phonics + Wushka phonics) - Áp dụng Shadowing techniques + công nghệ M-Speak để phát triển khả năng phát âm và kỹ năng nói - Áp dụng Hand-writing technology để phát triển kỹ năng viết - Thời lượng mỗi bài học ngắn, phù hợp với khả năng tập trung của bé ở lứa tuổi 3-8 - Monkey Go bổ sung phần Phonics bị thiếu khi chuyển từ app MS sang khóa MS, bổ trợ cho phương pháp học phonics đang được áp dụng ở sgk tiểu học, đồng thời có thêm những hoạt động giúp các bé luyện viết
A11: Input & output của khóa học | B11: Input - Trẻ 3-8 tuổi, ideally là chưa biết nhiều về tiếng Anh/ ít tiếp xúc với tiếng Anh - Bé trong độ tuổi 3-8 - Thích chơi xem media - Thích đọc truyện tranh - Biết một số ít từ vựng tiếng Anh, chưa thành thạo sử dụng các mẫu câu - Phát âm tiếng Anh chưa chuẩn - Khả năng viết còn chưa tốt - Nhu cầu bổ trợ cả 4 kỹ năng/giao tiếp được bằng tiếng Anh Outcome
A12: 11. Road map | B12: Roadmap dự kiến Dự kiến launch vào tuần cuối Tháng 4/2024
A13: Flow games trong lesson | B13: Flow tổng Flow minimal
A14: Tổng hợp games | B14: List game chốt
A15: 14. Điều kiện suggest khóa học | B15: Điều kiện suggest
A16: 15. Report khóa học | B16: - Report sau mỗi unit + Show những từ, âm, mẫu câu & truyện con học trong unit + Show điểm (sao) phát âm của hội thoại - Report tổng + Số từ + Số mẫu câu + Số truyện Reference Figma | D16: Link 1 Link 2
A17: 16. Reward | B17: - Sau mỗi lesson +15 xu. Học lại không cộng xu. - Sau mỗi unit +1 sticker
A18: 17. UI | B18: gồm 3-5 level với độ khó tăng dần flow bài học cố định, tuy nhiên có thể tự do chọn level
A19: 18. Review | B19: Sẽ có bài review sau 4 units (hoặc 5) Ôn lại các từ dễ (con đã nhớ) trước, rồi dần dần tới các từ con chưa nhớ
A20: 19. Timeline | B20: Timeline tổng
A21: Đề bài cho luồng mới | B21: - 2 luồng chính, 3-6t và 6-8t - Dùng luồng mới (content-based) nhưng dùng lại các ND đã có sẵn, sau đó sẽ update & thay dần các act - Transition giữa khóa M-ABC và MGo ở độ tuổi 3.5 và có thể tham khảo thêm luồng 3-6t của M-ABC - List game gồm minimum 15 games

Sheet MG - Phương pháp luận
A1: STT | B1: Phương pháp | C1: Mô tả | D1: Ứng dụng trong M.Go
A2: 1 | B2: Multimedia-based learning | C2: Phương pháp sử dụng nhiều học liệu khác nhau để dạy kiến thức. | D2: - Sử dụng hình ảnh, video, truyện, hội thoại để dạy từ vựng, cấu trúc, kỹ năng cho trẻ
A3: 2 | B3: Phonics Method | C3: Phương pháp dạy học sinh mối liên hệ giữa chữ cái (mặt chữ) và âm (sound) để giúp trẻ đọc và viết tốt hơn | D3: - Dạy trẻ mối liên hệ giữa chữ cái (letters), và âm (sound), cách ghép các âm để tạo thành từ hoàn chỉnh. - Các unit của M.Go sẽ dạy các từ phonics từ cơ bản đến nâng cao: âm đơn lẻ - âm ghép - cách ghép vần để đọc được các từ trong tiếng Anh - Phương pháp phonics giúp con phát âm chuẩn hơn, dễ dàng nhận diện để đọc chữ cái
A4: 3 | B4: Communicative Language Teaching | C4: Phương pháp tập trung rèn luyện năng lực giao tiếp cho trẻ thông qua sự tương tác của trẻ với các nội dung hướng tới mục đích giao tiếp. | D4: - Cung cấp các hội thoại định hướng giao tiếp, được cấu thành từ các từ vựng, mẫu câu đã được giới thiệu trước đó để giúp trẻ luyện tập giao tiếp trong các tình huống cụ thể, gần với đời thật
A5: 6 | B5: Story-based learning | C5: Story-based learning (Học thông qua truyện tranh tương tác): Các từ vựng và mẫu câu được đưa vào truyện một cách tự nhiên kèm theo cốt truyện hấp dẫn, khiến trẻ dễ dàng ghi nhớ kiến thức.Truyện giúp trẻ rèn luyện khả năng nắm bắt nghĩa của từ thông qua ngữ cảnh. Ngay cả khi trẻ không biết định nghĩa chính xác của một từ, trẻ vẫn có thể suy ra nghĩa của nó từ ngữ cảnh của truyện. | D5: - M.Go có xây dựng và thiết kế riêng bộ truyện theo các unit, nhằm giúp trẻ học từ vựng, câu ngữ cảnh thông qua việc đọc truyện.
B8: Kỹ năng | C8: Cách áp dụng trong games/ bài
B9: Kỹ năng nghe | C9: - Nghe các audio chuẩn bản ngữ trong các audio từ vựng, hội thoại, truyện, video - Tương tác với các game nghe audio và chọn đáp án
B10: Kỹ năng đọc | C10: - Đọc từ vựng, câu - Đọc hội thoại, đọc truyện - Chơi game - Trả lời các câu hỏi tương tác về nội dung truyện
B11: Kỹ năng nói | C11: - Nói từ, câu trong các game Speaking - Luyện nói hội thoại - Luyện tập kể lại truyện
B12: Kỹ năng viết | C12: - Độ tuổi nhỏ: + viết chữ cái, viết từ + ghép cụm từ, ghép câu đơn giản - Độ tuổi lớn + Ghép 2 vế câu + Ghép câu nhỏ vào đoạn văn lớn

Sheet MJ 5.0 - Outcome
A1: Cấp độ | B1: Từ vựng/Ngữ pháp | C1: 4 kỹ năng Nghe - Nói - Đọc - Viết | D1: Giao tiếp | E1: Ngữ âm - Phonics | F1: Story
A2: Level 0 | B2: - Tập trung ngôn ngữ đầu vào, giúp trẻ nhận biết các từ vựng ở các topic phổ biến (Động vật, Hoa quả, Đồ ăn, Đồ chơi,...), là tiền đề để học các cấp độ sau | C2: - Nghe hiểu và nhận diện được hình ảnh/ text của các từ vựng thuộc chủ đề gần gũi với cuộc sống hàng ngày - Làm quen với từ vựng thông qua các video bài hát, bài vè, truyện | D2: x | E2: x
A3: Level 1 | B3: - Nói được đúng từ vựng ở các topic rất phổ biến (Động vật, Hoa quả, Đồ ăn, Đồ chơi,...) | C3: - Được tiếp xúc với nhiều loại hình học liệu mới và yêu thích việc học tiếng Anh - Tăng cường nghe, đọc truyện và hội thoại - Tập nói từ, câu đơn giản; giới thiệu được bản thân, nói về những sự vật quanh mình - Làm quen và viết các chữ cái trong bảng chữ cái tiếng Anh | D3: - Chào hỏi, trao đổi được thông tin cá nhân cơ bản - Hiểu và trả lời được các câu hỏi về các vật phổ biến - Trả lời câu hỏi bằng các từ hoặc cụm từ ngắn | E3: - Bắt đầu học các âm đơn - Ghép từ có 1 âm tiết, học cách ghép âm lẻ | F3: - Nghe app đọc truyện đơn giản (tương đương level A-C ở MS) - Làm được CHTT bằng hình ảnh + audio
A4: Level 2 | B4: - Nói được các cụm từ và cấu trúc câu đơn giản | C4: - Đa dạng các loại học liệu để trẻ nghe - Đọc các truyện đơn giản, bắt đầu có cốt truyện để trẻ phát triển tính logic - Tiếp xúc và tập viết các nguyên âm đôi, đánh vần từ vựng dạng C-V-C (Consonant - Vowel - Consonant words) - Quen thuộc với việc giao tiếp bằng tiếng Anh, dễ dàng bật ra câu trả lời khi được hỏi
A5: Level 3 | B5: - Nói + sử dụng được phần lớn từ vựng xuất hiện trong các tình huống hàng ngày (A1-A2). - Nói được câu đơn ở các thì đơn giản: Hiện tại đơn, Hiện tại tiếp diễn, tương lai đơn | C5: - Các video sử dụng nhiều tình tiết đa dạng trong cuộc sống - Đọc truyện và hình thành khả năng phân tích truyện - Được học về phụ âm đôi, đánh vần các từ phức tạp hơn, dạng C-V-C, C-C-V-C - Giao tiếp về mọi người, sự vật, sự việc xung quanh, dễ dàng mô tả về ngoại hình, vị trí, hành động của họ | D5: - Giao tiếp cơ bản: nghe hiểu các câu hỏi WH-questions đơn giản => trả lời được bằng câu hoàn chỉnh - Giới thiệu được bản thân bằng một đoạn 3-4 câu liên tiếp | E5: - Ôn lại âm đơn lẻ + học cách ghép âm đôi - Đánh vần được những từ 1-2 âm tiết, có thể có âm đôi | F5: - Nghe app đọc truyện có scripts là câu + cốt truyện hấp dẫn - Làm được CHTT bằng cả text và audio/ hình ảnh
A6: Level 4 | B6: - Nói được cụm từ/câu đơn + câu phủ định, cảm thán, câu hỏi + một số câu phức có liên từ đơn giản (and, but) | C6: - Nghe và đọc truyện, hội thoại với số lượng từ vựng nhiều và phức tạp hơn, ở nhiều chiều thời gian - Đa dạng các nguyên âm và phụ âm đôi, ở thời điểm này trẻ có thể vận dụng kĩ năng đánh vần để đọc được truyện thiếu nhi tiếng Anh - Trẻ có thể mô tả sự việc đã xảy ra trong quá khứ, trong tương lai gần khi giao tiếp
A7: Level 5 | B7: - Sử dụng thành thạo các từ vựng hàng ngày + các từ vựng khó hơn (A2-B1) - Nói được đa dạng loại câu đơn + phức. Có thể dễ dàng chia sẻ thông tin + cảm nghĩ, cảm xúc bản thân. - Sử dụng được các thì: Quá Khứ đơn, Hiện tại hoàn thành | C7: - Thời điểm này trẻ gần như hoàn thiện về khả năng giao tiếp so với nhu cầu thường ngày của trẻ - Được giới thiệu tổng 100 âm phonics, trẻ dễ dàng đánh vần một từ chưa gặp và có khả năng đọc tốt - Trẻ dễ dàng phân tích các truyện hình ngắn về từ vựng, tình tiết truyện, trả lời các câu hỏi đọc hiểu sau truyện - Viết: tô các chữ cái, luyện tập ghép câu, điền từ vào câu | D7: - Giao tiếp thực tế: nghe hiểu tốt các câu hỏi, câu tường thuật, câu cảm thán - Đưa ra được ý kiến cá nhân | E7: - Học tiếp các blended sounds (2-3 letters) - Đánh vần được các từ khó hơn, có thể bao gồm blended sound đến 3 chữ cái | F7: - Đọc được truyện có đến 4-5 câu mỗi trang + informational texts - Làm được CHTT bằng các loại data, mạnh về comprehension + details

Sheet MJ 5.0 - Landing page
A1: Level | B1: Độ tuổi | C1: Tagline | D1: Phương pháp | E1: Số bài học/ hoạt động | F1: Giới thiệu (biểu thị bằng chart ở từng level) | G1: Phân loại theo cấp độ | H1: Outcome | I1: Highlight
A2: 0 | B2: 0-3 | C2: Khóa học với định hướng tập trung từ vựng, áp dụng các phương pháp Giáo dục sớm | D2: 1. Phương pháp chụp hình nguyên từ - Học từ vựng thông qua ghi nhớ mặt chữ viết, hình ảnh và audio giọng đọc. - Hiệu quả đối với các bạn nhỏ khi bán cầu não phải đang trong quá trình phát triển mạnh và việc học thông qua hình ảnh, chụp hình được tiến hành một cách rất dễ dàng và tự nhiên. Khi đó, việc giới thiệu một từ vựng gốc, không phân tách từng chữ cái với trẻ sẽ giống với việc giới thiệu một hình ảnh. Trẻ không cần kiến thức về chữ viết cũng có thể nhớ được cách viết của từ vựng đó. 2. Phương pháp đa giác quan - Học từ vựng thông qua việc sử dụng nhiều giác quan cùng lúc - Trẻ được nghe giọng đọc, hiệu ứng âm thanh. Trẻ được nhìn chữ cùng hình ảnh, video mô tả sinh động, chính xác, trực tiếp ấn chạm thông qua các trò chơi tương tác. 3. Phương pháp tráo thẻ nhanh - Glenn Doman - Học từ vựng thông qua thẻ từ với các quy chuẩn nhất định. - Các từ vựng được giới thiệu 1 set từ vựng cùng nhau thông qua các hình hình ảnh rõ ràng, chân phương, không có các yếu tố gây nhiễu. Tốc độ tráo thẻ nhanh, từ 0.7-1s. 4. Phương pháp học thông qua trò chơi - Phương pháp đưa các nội dung tri thức và kỹ năng muốn truyền tải cho con trẻ lồng ghép vào các trò chơi có tính định hướng. - Mỗi bài học có từ 5-7 hoạt động là các hoạt động trò chơi tương tác khác nhau kích thích tư duy & hứng thú học của trẻ xuyên suốt quá trình học tập. | E2: 600+ hoạt động 600+ từ vựng | F2: - 700+ từ vựng phổ biến - 50+ bài hát, bài vè, truyện - Học từ vựng theo phương pháp Giáo dục sớm | G2: - 2 loại từ vựng : + Từ vựng chủ đề + Từ vựng phổ biến | H2: - Nghe hiểu và nhận diện được hình ảnh/ text của các từ vựng thuộc chủ đề gần gũi với cuộc sống hàng ngày | I2: - Thời lượng mỗi bài học ngắn, các hoạt động được thiết kế phù hợp với khả năng học và tương tác của trẻ 0-3 tuổi - Tích lũy kho từ vựng chủ đề và từ vựng phổ biến, là tiền đề để học lên các cấp độ tiếp theo.
A3: 1 | B3: 45359 | C3: Khóa học phát triển 4 kỹ năng Nghe - Nói - Đọc - Viết | D3: 1. Multimedia-based Learning - Học qua đa phương tiện - Phương pháp sử dụng nhiều học liệu khác nhau: hình ảnh, video, truyện, hội thoại,... để dạy kiến thức, kỹ năng cho trẻ. 2. Phonics Method - Phương pháp ngữ âm - Phương pháp dạy mối liên hệ giữa chữ cái (letter) và âm (sound), cách ghép các âm để tạo thành từ hoàn chỉnh, giúp trẻ nhận diện được mặt chữ, phát âm chuẩn hơn, đọc và viết tốt hơn. - Các phonics được lồng ghép theo cấp độ từ cơ bản đến nâng cao: âm đơn lẻ - âm ghép - cách ghép vần để đọc được các từ trong tiếng Anh. 3. Communicative Language Teaching - Dạy ngôn ngữ qua giao tiếp - Phương pháp tập trung rèn luyện năng lực giao tiếp cho trẻ thông qua sự tương tác của trẻ với các nội dung hướng tới mục đích giao tiếp. - Khóa học cung cấp các hội thoại theo định hướng giao tiếp, được cấu thành từ các từ vựng, mẫu câu đã được giới thiệu trước đó để giúp trẻ luyện tập giao tiếp trong các tình huống cụ thể, gần với đời thật. | E3: 640+ hoạt động | F3: - 20 âm đơn - 300+ từ vựng - 60+ video, bài hát, hội thoại, truyện - Làm quen với Cambridge Starters | G3: - 20 chủ đề quen thuộc: Con vật, Hoa quả, Đồ chơi,... * Kỹ năng nghe: - Nghe và hiểu được tên riêng, tên gọi đồ vật, sự vật rất đơn giản, quen thuộc. - Nghe, hiểu và làm theo những yêu cầu đơn giản, tương tác chọn đáp án. * Kỹ năng nói: - Biết nhắc lại, nói tên riêng, tên đồ vật, sự vật rất đơn giản, quen thuộc. - Phát âm tương đối rõ ràng các từ đơn lẻ của chủ đề được học. * Kỹ năng đọc: - Đọc từ vựng, câu đơn giản trong hội thoại, truyện. - Trả lời các câu hỏi rất đơn giản về truyện. * Kỹ năng viết: - Tập tô chữ cái đơn lẻ. * Ngữ âm: - Nhận biết và phát âm được 20 âm đơn lẻ. - Học cách ghép các âm vào từ. | H3: - Được tiếp xúc với nhiều loại hình học liệu mới và yêu thích việc học tiếng Anh - Tăng cường nghe, đọc truyện và hội thoại - Tập nói từ, câu đơn giản; giới thiệu được bản thân, nói về những sự vật quanh mình - Làm quen và viết các chữ cái trong bảng chữ cái tiếng Anh | I3: - Thời lượng mỗi bài học ngắn, phù hợp với khả năng tập trung của trẻ ở lứa tuổi 3-8. - Hệ thống học liệu đa dạng, hiện đại: từ vựng, câu, truyện tranh, video, bài hát, trò chơi tương tác,... với độ khó tăng dần theo từng cấp độ. - Sử dụng phương pháp Jolly Phonics + Wushka phonics được công nhận trên thế giới, giúp trẻ nhận diện được mặt chữ và ghép thành từ hoàn chỉnh. - Áp dụng phương pháp Shadowing và công nghệ M-Speak để phát triển khả năng phát âm và kỹ năng nói. - Kho truyện được thiết kế riêng, minh họa hiện đại, nội dung hấp dẫn, giúp phát triển khả năng đọc hiểu. - Áp dụng công nghệ Hand-writing để phát triển kỹ năng viết. | J3: Thiếu kĩ năng nghe
A4: 2 | E4: 640+ hoạt động | F4: - 20 âm đơn và âm đôi - 300+ từ vựng - 60+ video, bài hát, hội thoại, truyện - Luyện tập theo Cambridge Starters | G4: - 20 chủ đề quen thuộc: Đồ ăn, Quần áo, Nhà cửa,... * Kỹ năng nghe: - Nghe và hiểu được tên gọi đồ vật, sự vật đơn giản, quen thuộc. - Nghe, hiểu và làm theo những yêu cầu đơn giản, tương tác chọn đáp án. * Kỹ năng nói: - Phát âm rõ ràng các từ của chủ đề được học. - Nói được các cụm từ và cấu trúc câu đơn giản. * Kỹ năng đọc: - Đọc từ vựng, câu đơn giản trong hội thoại, truyện. - Trả lời các câu hỏi rất đơn giản về truyện. * Kỹ năng viết: - Bắt đầu tập tô tổ hợp 1 - 2 chữ cái. * Ngữ âm: - Bắt đầu nhận biết và phát âm được âm đôi. - Học cách ghép các âm vào từ. | H4: - Đa dạng các loại học liệu để trẻ nghe - Đọc các truyện đơn giản, bắt đầu có cốt truyện để trẻ phát triển tính logic - Tiếp xúc và tập viết các nguyên âm đôi, đánh vần từ vựng dạng C-V-C (Consonant - Vowel - Consonant words) - Quen thuộc với việc giao tiếp bằng tiếng Anh, dễ dàng bật ra câu trả lời khi được hỏi
A5: 3 | E5: 640+ hoạt động | F5: - 20 âm đôi - 400+ từ vựng - 60+ video, bài hát, hội thoại, truyện - Sẵn sàng thi chứng chỉ Cambridge Starters | G5: - 20 chủ đề quen thuộc: Thời tiết, Địa điểm, Phương tiện,... * Kỹ năng nghe: - Nghe và hiểu được tên gọi đồ vật, sự vật, hành động. - Nghe, hiểu và làm theo những yêu cầu để tương tác trong bài học. * Kỹ năng nói: - Phát âm rõ ràng các từ vựng và mẫu câu của chủ đề được học. - Nói được câu trong hội thoại và truyện. * Kỹ năng đọc: - Đọc hiểu từ vựng, câu đơn giản trong hội thoại, truyện. - Trả lời các câu hỏi về ý nghĩa truyện, sắp xếp tình tiết truyện. * Kỹ năng viết: - Tô các tổ hợp âm đôi. * Ngữ âm: - Nhận biết và phát âm được các âm đôi. - Ghép các âm vào từ. | H5: - Các video sử dụng nhiều tình tiết đa dạng trong cuộc sống - Đọc truyện và hình thành khả năng phân tích truyện - Được học về phụ âm đôi, đánh vần các từ phức tạp hơn, dạng C-V-C, C-C-V-C - Giao tiếp về mọi người, sự vật, sự việc xung quanh, dễ dàng mô tả về ngoại hình, vị trí, hành động của họ
A6: 4 | E6: 700+ hoạt động | F6: - 20 âm đôi - 600+ từ vựng - 60+ video, bài hát, hội thoại, truyện - Làm quen với Cambridge Movers | G6: - 20 chủ đề quen thuộc: Thể thao, Thiên nhiên, Nghề nghiệp,... * Kỹ năng nghe: - Nghe, hiểu, nắm rõ được tên gọi đồ vật, sự vật, hành động. - Nghe, hiểu và làm theo những yêu cầu để tương tác trong bài học. * Kỹ năng nói: - Phát âm rõ ràng các từ vựng và mẫu câu của chủ đề được học. - Nói được câu trong hội thoại và truyện. * Kỹ năng đọc: - Đọc hiểu, đoán được nghĩa từ vựng, câu trong ngữ cảnh. - Trả lời các câu hỏi về ý nghĩa truyện, sắp xếp tình tiết truyện. * Kỹ năng viết: - Tô các tổ hợp âm đôi. * Ngữ âm: - Nhận biết và phát âm được các âm đôi. - Ghép các âm vào từ. | H6: - Nghe và đọc truyện, hội thoại với số lượng từ vựng nhiều và phức tạp hơn, ở nhiều chiều thời gian - Đa dạng các nguyên âm và phụ âm đôi, ở thời điểm này trẻ có thể vận dụng kĩ năng đánh vần để đọc được truyện thiếu nhi tiếng Anh - Trẻ có thể mô tả sự việc đã xảy ra trong quá khứ, trong tương lai gần khi giao tiếp
A7: 5 | E7: 700+ hoạt động | F7: - 20 âm đôi và âm ba - 800+ từ vựng - 60+ video, bài hát, hội thoại, truyện - Luyện tập theo Cambridge Movers | G7: - 20 chủ đề quen thuộc: Sức khỏe, Công cụ, Công nghệ,... * Kỹ năng nghe: - Nghe, hiểu, nắm rõ được tên gọi đồ vật, sự vật, hành động. - Nghe, hiểu và làm theo những yêu cầu để tương tác trong bài học. * Kỹ năng nói: - Phát âm rõ ràng các từ vựng và mẫu câu của chủ đề được học. - Nói được câu trong hội thoại và truyện. * Kỹ năng đọc: - Đọc hiểu, đoán được nghĩa từ vựng, câu trong ngữ cảnh. - Trả lời các câu hỏi về ý nghĩa truyện, sắp xếp tình tiết truyện. * Kỹ năng viết: - Tô các tổ hợp phụ âm được cấu tạo bởi 2 - 3 chữ cái. * Ngữ âm: - Nhận biết và phát âm được các âm đôi và âm gồm 3 chữ cái. - Ghép các âm vào từ. | H7: - Thời điểm này trẻ gần như hoàn thiện về khả năng giao tiếp so với nhu cầu thường ngày của trẻ - Được giới thiệu tổng 100 âm phonics, trẻ dễ dàng đánh vần một từ chưa gặp và có khả năng đọc tốt - Trẻ dễ dàng phân tích các truyện hình ngắn về từ vựng, tình tiết truyện, trả lời các câu hỏi đọc hiểu sau truyện

Sheet MJ 5.0 - Logic tính sao Kĩ năng
A1: Nhóm game | B1: Level | C1: ID Game | D1: Tên game | E1: Kĩ năng | F1: Cách tính điểm
A2: Nhóm 1 | C2: BE.RST02 | D2: Multiple choice story (chọn ảnh) | E2: Listening | F2: 1. Tính kết quả của lần chơi đầu tiên 2. Cách tính điểm của 1 game: 2.1. Game có 2 lượt chơi: - Sai lần đầu chơi cả 2 lượt: 40 điểm - Sai lần đầu chơi 1 lượt: 60 điểm - Đúng lần đầu chơi cả 2 lượt: 100 điểm 2.2. Game có 3 lượt chơi: - Sai lần đầu chơi cả 3 lượt: 40 điểm - Sai lần đầu chơi 2 lượt: 60 điểm - Sai lần đầu chơi 1 lượt: 80 điểm - Đúng lần đầu chơi cả 3 lượt: 100 điểm 2.3. Game có 1 lượt chơi: - Không có lần drag sai (100 điểm) - 1 lần drag sai (80 điểm) - >=2 lần drag sai (60 điểm) 3. Tính sao hiển thị: - Count số lần chơi các game cùng 1 kĩ năng trong 7 ngày gần nhất - Tính trung bình số điểm/lần hoàn thành game - Quy đổi thành đơn vị SAO bằng cách chia cho 20: 1=>5 SAO, làm tròn đến đơn vị 0.5 SAO
C3: BE.RP05 | D3: Multiple choice (cho audio chọn ảnh) | E3: Listening | G3: Phân biệt các skills
C4: EE.RP01 | D4: Multiple choice - Audio | E4: Listening | G4: cho audio chọn text | H4: listening
C5: BE.RP04 | D5: Listen and choose picture | E5: Listening | G5: cho audio chọn ảnh | H5: listening
C6: MG.MC02 | D6: Multiple choice (ảnh) | E6: Listening | G6: cho ảnh chọn audio | H6: listening
C7: BE.RV03 | D7: Listen and choose (cho audio chọn text) | E7: Listening | G7: cho ảnh chọn text | H7: reading
C8: BE.RV06 | D8: Multiple choice (cho audio chọn text) | E8: Listening | G8: cho text chọn ảnh | H8: reading
C9: BE.PS01 | D9: Brick layer | E9: Reading | G9: cho text chọn audio | H9: reading
C10: BE.RS02 | D10: Word machine | E10: Reading
C11: EE.RV01 | D11: Multiple choice - Image | E11: Listening
C12: EE.RW08 | D12: Multi-bubble | E12: Listening
A13: Nhóm 2 | C13: EE.GS01 | D13: Letter Fishing | E13: Listening | F13: 1. Tính kết quả theo số lần tap (cá) của user 2. Cách tính điểm của 1 game: - User thao tác tap trên màn hình >12 lần: 40 điểm - User thao tác tap trên màn hình 9-12 lần: 60 điểm - User thao tác tap trên màn hình 5-8 lần: 80 điểm - User thao tác tap trên màn hình 4 lần: 100 điểm 3. Tính sao hiển thị: - Count số lần chơi các game cùng 1 kĩ năng trong 7 ngày gần nhất - Tính trung bình số điểm/lần hoàn thành game - Quy đổi thành đơn vị SAO bằng cách chia cho 20: 1=>5 SAO, làm tròn đến đơn vị 0.5 SAO
D14: Word Fishing | E14: Reading | F14: 1. Tính kết quả theo số lần tap (cá) của user 2. Cách tính điểm của 1 game: - User thao tác tap trên màn hình >16 lần: 40 điểm - User thao tác tap trên màn hình 13-16 lần: 60 điểm - User thao tác tap trên màn hình 9-12 lần: 80 điểm - User thao tác tap trên màn hình 8 lần: 100 điểm 3. Tính sao hiển thị: - Count số lần chơi các game cùng 1 kĩ năng trong 7 ngày gần nhất - Tính trung bình số điểm/lần hoàn thành game - Quy đổi thành đơn vị SAO bằng cách chia cho 20: 1=>5 SAO, làm tròn đến đơn vị 0.5 SAO
C15: BE.RVS02 | D15: Jumbled pages | E15: Reading | F15: 1. Tính kết quả theo số lần drag (ảnh) của user 2. Cách tính điểm của game: - User thao tác drag trên màn hình >8 lần: 40 điểm - User thao tác drag trên màn hình 7-8 lần: 60 điểm - User thao tác drag trên màn hình 5-6 lần: 80 điểm - User thao tác drag trên màn hình 4 lần: 100 điểm 3. Tính sao hiển thị: - Count số lần chơi các game cùng 1 kĩ năng trong 7 ngày gần nhất - Tính trung bình số điểm/lần hoàn thành game - Quy đổi thành đơn vị SAO bằng cách chia cho 20: 1=>5 SAO, làm tròn đến đơn vị 0.5 SAO
C16: BE.RV08 | D16: Catching fireflies | E16: Reading | F16: 1. Tính kết quả theo số lần drag (đom đóm) của user 2. Cách tính điểm của 1 game: - User thao tác drag trên màn hình >20 lần: 20 điểm - User thao tác drag trên màn hình 17-20 lần: 40 điểm - User thao tác drag trên màn hình 13-16 lần: 60 điểm - User thao tác drag trên màn hình 11-12 lần: 80 điểm - User thao tác drag trên màn hình 10 lần: 100 điểm 3. Tính sao hiển thị: - Count số lần chơi các game cùng 1 kĩ năng trong 7 ngày gần nhất - Tính trung bình số điểm/lần hoàn thành game - Quy đổi thành đơn vị SAO bằng cách chia cho 20: 1=>5 SAO, làm tròn đến đơn vị 0.5 SAO
A17: Nhóm 3 | C17: BE.GP05 | D17: Trace the letter (Tracing) | E17: Writing | F17: 1. Tính kết quả của lượt tô tự do (lượt cuối) Với những âm có 2-3 chữ cái: user cần tô cả 2-3 chữ cái thì mới tính là 1 lượt, không tính lẻ theo từng letter riêng 2. Cách tính điểm: * Với luồng < 3 tuổi: không áp dụng Hand-writing mà chỉ tô trên nét đứt - User tô đúng từ lần 1: 100 điểm - User tô đúng từ lần 2: 80 điểm - User tô đúng từ lần 3: 60 điểm - User tô đúng ở lần cuối (drag): 40 điểm * Với luồng >= 3 tuổi: áp dụng Hand-writing - Hệ thống nhận đúng chữ: 100 điểm - Hệ thống không nhận diện được chữ: 40 điểm 3. Tính sao hiển thị: - Count số lần chơi các game cùng 1 kĩ năng trong 7 ngày gần nhất - Tính trung bình số điểm/lần hoàn thành game - Quy đổi thành đơn vị SAO: 1=>5 SAO, làm tròn đến đơn vị 0.5 SAO
A18: Nhóm 4 | C18: BE.PV02 | D18: Cat teaching AI | E18: Speaking | F18: 1. Tính kết quả của lần thu âm cuối cùng 2. Cách tính điểm của 1 lượt: - TH1: match >=80% => 100 điểm - TH2: match >=60% => 80 điểm - TH3: 50% =< match <60% => 60 điểm - TH4: match < 50% => 40 điểm 3. Tính sao hiển thị: - Count số lần chơi các game cùng 1 kĩ năng trong 7 ngày gần nhất - Tính trung bình số điểm/lần hoàn thành game - Quy đổi thành đơn vị SAO: 1=>5 SAO, làm tròn đến đơn vị 0.5 SAO
C19: BE.PV03 | D19: Robot teaching AI | E19: Speaking
C20: EE.PS01 | D20: Speaking sentence (AI) | E20: Speaking
D21: Chunking speaking | E21: Speaking
C22: BE.PD01 | D22: Dialog 1 | E22: Speaking
C23: BE.PS04 | D23: Speaking competition | E23: Speaking

Sheet So sánh MJ 4.0 vs. MJ 5.0
A1: So sánh sản phẩm - MONKEY JUNIOR 4.0 và MONKEY JUNIOR 5.0
A3: Tiêu chí | B3: Phiên bản hiện tại | C3: Monkey Junior 5.0
A4: Tổng quan app | B4: Home course gồm nhiều khóa học, mỗi khóa học có mục tiêu học khác nhau để bộ trợ riêng cho từng kỹ năng | C4: Home course gồm 1 lộ trình chính giúp phát triển toàn diện 4 kỹ năng Nghe - Nói - Đọc - Viết cho trẻ từ 0-8 tuổi kèm theo mục Siêu Việt (hệ thống các khóa học bổ trợ của MJ 4.0)
A5: Đối tượng học | B5: Trẻ độ tuổi 0-11 | C5: Lộ trình chính dành cho trẻ độ tuổi 0-8
A6: Lộ trình học | B6: - MABC: 3 cấp độ, trẻ tự do chọn cấp độ, topic học - MS: đặc trưng của việc đọc truyện theo cấp độ >> có nhiều cấp độ đọc truyện - MSP: 4 cấp độ, trẻ được học unit đầu mỗi cấp độ | C6: Lộ trình chính gồm 6 cấp độ: - Cấp độ 0 (0-3 tuổi): nghe hiểu, nhận diện được hình ảnh và mặt chữ của các từ vựng thuộc chủ đề gần gũi với cuộc sống hàng ngày - Cấp độ 1-5 (3-8 tuổi): phát triển toàn diện 4 kỹ năng Nghe - Nói - Đọc - Viết Mỗi level mở 01 bài học đầu tiên. Users được phép học thử các levels để quyết định sẽ học level nào
A7: Nội dung học | B7: Chi tiết xem product profile từng khóa học - MABC: học từ vựng - MSP: luyện nói và giao tiếp - MS: đọc truyện theo cấp độ | C7: Các khóa học khác: giữ nguyên Lộ trình chính gồm: - Âm phonics: 100 âm - Từ vựng phonics: 400 từ - Từ vựng ghép vần: 200 từ - Từ vựng chủ đề: 400 từ (bao gồm 100 từ trùng với từ vựng phonics) - Câu: 100 câu - Hội thoại: 100 hội thoại - Truyện: 50 truyện - Video: 150 video Nội dung học được xây dựng hoàn toàn mới, không trùng lặp với các khóa khác Benchmark: - Từ vựng: CEFR - Tổng quan kiến thức, kĩ năng: theo Cambridge (Starters, Movers)
A8: Chương trình học | C8: Khối lượng kiến thức khổng lồ được chia thành nhiều level, nhiều unit, mỗi unit được chia ra 7 bài học giúp trẻ dễ dàng nắm bắt và thực hành nội dung học, sử dụng nhiều kĩ năng ngôn ngữ khác nhau
A9: Cấu trúc bài học | B9: Chi tiết xem product profile từng khóa học | C9: Lộ trình học chính chia theo 2 giai đoạn: * Level 0 (0-3 tuổi) Ở Cấp độ 0, một đơn vị bài học gồm hai chủ đề nhỏ với 16 từ vựng được học trong 5 bài học. 5 bài học này gồm 2 loại bài học tương ứng. Từ bài học 1 đến bài học 4, mỗi bài học trẻ được học 8 từ vựng trong 2 chủ đề, như vậy mỗi từ được lặp lại 2 lần. Trong bài học 5, trẻ được xem video bài hát/ bài vè/ truyện. * Level 1-5 (3-8 tuổi) Mỗi cấp độ từ 1-5 bao gồm 140 bài học, trong đó có 20 chủ đề, và mỗi chủ đề gồm 7 bài học. Tất cả các chủ đề đều có 7 từ vựng chính, 1 âm phonics và 2 từ phonics ghép âm, 1 mẫu câu, 1 hội thoại, 1 truyện/video chứa mẫu câu.
A10: Phương pháp học | B10: - MABC: các PP GDS - MSP: PP Giao tiếp, KT Nhại lại (Shadowing), PP Chunking - MS course: PP Học thông qua truyện tranh tương tác - MS app: thêm PP Phonics | C10: * Level 0 (0-3 tuổi): - Phương pháp Chụp hình nguyên từ - Phương pháp Tráo thẻ nhanh - Glenn Doman - Phương pháp Đa giác quan - Phương pháp Học thông qua trò chơi * Level 1-5 (3-8 tuổi): - Phương pháp Học qua đa phương tiện - Phương pháp Ngữ âm - Phương pháp Dạy ngôn ngữ qua giao tiếp
A11: Outcomes | B11: Chi tiết xem product profile từng khóa học | C11: Xem chi tiết ở đây
A12: Hoạt động trò chơi | B12: Mỗi khóa học có hệ thống trò chơi riêng phục vụ mục đích của từng khóa (chi tiết xem product profile từng khóa) | C12: - Các khóa học bổ trợ vẫn giữ nguyên hệ thống trò chơi - Lộ trình chính được bổ sung thêm các trò chơi mới được minh họa mới theo phong cách hiện đại, sinh động, hấp dẫn trẻ nhỏ - Các hoạt động được phân loại theo mục đích dạy kỹ năng: luyện nghe và phát âm, ghép câu, giao tiếp, đọc hiểu, viết chữ. - Các trò chơi được thiết kế với tính tương tác cao: video tương tác, game tô chữ áp dụng công nghệ nhận diện chữ viết,...
A13: Công nghệ | B13: Công nghệ MSpeak độc quyền chấm điểm phát âm bằng trí tuệ nhân tạo, dành riêng cho trẻ em giúp kiểm tra, chấm điểm phát âm dựa trên độ chính xác của các âm, trọng âm | C13: - Công nghệ MSpeak độc quyền chấm điểm phát âm dựa trên độ chính xác của các âm, trọng âm - Công nghệ nhận diện chữ viết Handwriting đánh giá độ chính xác khi viết chữ của trẻ - Video tương tác giúp tăng sự hứng thú của trẻ
A14: Phần thưởng | B14: - Monkey Shop - Xu sau bài học - Sticker sau unit | C14: Không thay đổi

Sheet So sánh list từ
A1: =COUNTA(A3:A1299) -> 1179 | B1: =COUNTA(B3:B1299) -> 919 | C1: 442 | D1: =C1/B1 -> 0.48095756 | F1: =COUNTA(F3:F1299) -> 1045 | G1: =COUNTA(G3:G1299) -> 427 | H1: 292 | I1: =H1/G1 -> 0.68384075 | K1: =COUNTA(K3:K1299) -> 320 | L1: =COUNTA(L3:L1299) -> 278 | M1: 63 | N1: =M1/L1 -> 0.22661871 | P1: =COUNTA(P3:P1299) -> 324 | Q1: =COUNTA(Q3:Q1299) -> 350 | R1: 90 | S1: =R1/Q1 -> 0.25714286
A2: Tổng từ MJ | B2: Tổng từ Cambridge | C2: Số từ trùng | D2: % trùng | F2: Level 0-1 | G2: A1 Starters | H2: Số từ trùng | I2: % trùng | K2: Level 2-3 | L2: A1 Movers | M2: Số từ trùng | N2: % trùng | P2: Level 4-5 | Q2: A2 Flyers | R2: Số từ trùng | S2: % trùng
A3: cat | B3: animal | F3: cat | G3: animal | K3: watermelon | L3: bat | P3: flashlight | Q3: beetle
A4: cow | B4: bear | F4: cow | G4: bear | K4: orange | L4: cage | P4: sleeping bag | Q4: butterfly
A5: dog | B5: bee | F5: dog | G5: bee | K5: cherry | L5: dolphin | P5: tent | Q5: camel
A6: pig | B6: bird | F6: pig | G6: bird | K6: papaya | L6: fly | P6: compass | Q6: creature
A7: eye | B7: cat | F7: eye | G7: cat | K7: jacket | L7: kangaroo | P7: sloth | Q7: dinosaur
A8: ear | B8: chicken | F8: ear | G8: chicken | K8: sweater | L8: kitten | P8: snail | Q8: eagle
A9: arm | B9: cow | F9: arm | G9: cow | K9: coat | L9: lion | P9: tortoise | Q9: extinct
A10: leg | B10: crocodile | F10: leg | G10: crocodile | K10: shirt | L10: panda | P10: koala | Q10: fur
A11: popcorn | B11: dog | F11: popcorn | G11: dog | K11: yacht | L11: parrot | P11: smock | Q11: insect
A12: candy | B12: donkey | F12: candy | G12: donkey | K12: ship | L12: penguin | P12: paintbrush | Q12: nest
A13: jello | B13: duck | F13: jello | G13: duck | K13: boat | L13: puppy | P13: palette | Q13: octopus
A14: ice cream | B14: elephant | F14: ice cream | G14: elephant | K14: ferry | L14: rabbit | P14: easel | Q14: swan
... A272: fireplace | B272: mouse | F272: fireplace | G272: English | K272: black | L272: hospital | P272: throw | Q272: December
A273: hammer | B273: music | F273: hammer | G273: eraser | L273: ill | P273: wrestle | Q273: ambulance
A274: broom | B274: number | F274: broom | G274: example | K274: sweater | L274: matter | P274: wrap | Q274: bicycle
A275: towel | B275: open | F275: towel | G275: find | K275: watermelon | L275: nurse | P275: wrinkle | Q275: fire engine
A276: elderly man | B276: page | F276: elderly man | G276: floor | K276: jacket | L276: sick | P276: knee | Q276: fire truck
A277: elderly woman | B277: painting | F277: elderly woman | G277: keyboard | K277: yacht | L277: stomach-ache | P277: knock | Q277: journey
A278: teenager | B278: part | F278: teenager | G278: computer | K278: yo-yo | L278: temperature | Q278: lift
A279: kid | B279: pen | F279: kid | G279: learn | K279: fox | L279: tired | P279: engineer | Q279: motorway
A280: worm | B280: pencil | F280: worm | G280: lesson | K280: zoo | L280: toothache | P280: flashlight | Q280: passenger
A281: moth | B281: poster | F281: moth | G281: letter | K281: queen | P281: sloth | Q281: platform
A282: slug | B282: question | F282: slug | G282: line | K282: cheese | P282: smock | Q282: racing
A283: mantis | B283: read | F283: mantis | G283: listen | K283: peach | P283: cave | Q283: ride
A284: slide (v) | B284: right | F284: slide | G284: look | K284: scooter | P284: rose | Q284: railway
A285: carry | B285: ruler | F285: carry | G285: mouse | K285: cooker | P285: throne | Q285: rocket
A286: dip | B286: school | F286: dip | G286: music | K286: bowling | P286: ice skates | Q286: spaceship
A287: drop | B287: sentence | F287: drop | G287: number | K287: goat | P287: amusement park | Q287: taxi
A288: juice | B288: sit | F288: juice | G288: open | K288: aloe | P288: athlete | Q288: tour
A289: water | B289: spell | F289: water | G289: page | K289: soup | P289: garden | Q289: traffic
A290: coffee | B290: stand | F290: coffee | G290: painting | K290: cloudy | P290: claw | Q290: wheel
A291: hot chocolate | B291: story | F291: hot chocolate | G291: paper | K291: boil | P291: hawk | Q291: fog
A292: baker | B292: teacher | F292: baker | G292: part | K292: soy | P292: reindeer | Q292: foggy
... A323: pot | B323: photo | F323: pot | G323: boat | K323: blazer | P323: stream | Q323: taxi
A324: rainbow | B324: piano | F324: rainbow | G324: book | P324: throne | Q324: waiter
A325: sea | B325: play | F325: sea | G325: bounce | P325: wrist | Q325: air
A326: Earth | B326: ride | F326: Earth | G326: camera | P326: knit | Q326: bridge
A327: cloud | B327: run | F327: cloud | G327: catch | P327: knight | Q327: castle
...

Sheet Sheet14
A2: Cấp độ | B2: Chủ đề | C2: Ngữ âm | D2: Nghe | E2: Nói | F2: Đọc | G2: Viết
A3: 1 | B3: 20 chủ đề quen thuộc: Con vật, Hoa quả, Đồ chơi,... | C3: - Nhận biết và phát âm được 20 âm đơn lẻ. - Học cách ghép các âm vào từ. | D3: - Nghe và hiểu được tên riêng, tên gọi đồ vật, sự vật rất đơn giản, quen thuộc. - Nghe, hiểu và làm theo những yêu cầu đơn giản, tương tác chọn đáp án. | E3: - Biết nhắc lại, nói tên riêng, tên đồ vật, sự vật rất đơn giản, quen thuộc. - Phát âm tương đối rõ ràng các từ đơn lẻ của chủ đề được học. | F3: - Đọc từ vựng, câu trong hội thoại, truyện. - Trả lời các câu hỏi rất đơn giản về truyện. | G3: - Tập tô chữ cái đơn lẻ.
A4: 2 | B4: 20 chủ đề quen thuộc: Đồ ăn, Quần áo, Nhà cửa,... | C4: - Bắt đầu nhận biết và phát âm được âm đôi. - Học cách ghép các âm vào từ. | D4: - Nghe và hiểu được tên gọi đồ vật, sự vật đơn giản, quen thuộc. - Nghe, hiểu và làm theo những yêu cầu đơn giản, tương tác chọn đáp án. | E4: - Phát âm rõ ràng các từ của chủ đề được học. - Nói được các cụm từ và cấu trúc câu đơn giản. | F4: - Đọc từ vựng, câu trong hội thoại, truyện. - Trả lời các câu hỏi rất đơn giản về truyện. | G4: - Bắt đầu tập tô tổ hợp 1 - 2 chữ cái.
A5: 3 | B5: 20 chủ đề quen thuộc: Thời tiết, Địa điểm, Phương tiện,... | C5: - Nhận biết và phát âm được các âm đôi. - Ghép các âm vào từ. | D5: - Nghe và hiểu được tên gọi đồ vật, sự vật, hành động. - Nghe, hiểu và làm theo những yêu cầu để tương tác trong bài học. | E5: - Phát âm rõ ràng các từ vựng và mẫu câu của chủ đề được học. - Nói được câu trong hội thoại và truyện. | F5: - Đọc hiểu từ vựng, câu đơn giản trong hội thoại, truyện. - Trả lời các câu hỏi về ý nghĩa truyện, sắp xếp tình tiết truyện. | G5: - Tô các chữ cái trong tổ hợp âm đôi.
A6: 4 | B6: 20 chủ đề quen thuộc: Thể thao, Thiên nhiên, Nghề nghiệp,... | C6: - Nhận biết và phát âm được các âm đôi. - Ghép các âm vào từ. | D6: - Nghe, hiểu, nắm rõ được tên gọi đồ vật, sự vật, hành động. Nghe, hiểu và làm theo những yêu cầu để tương tác trong bài học. | E6: - Phát âm rõ ràng các từ vựng và mẫu câu của chủ đề được học. - Nói được câu trong hội thoại và truyện. | F6: - Đọc hiểu, đoán được nghĩa từ vựng, câu trong ngữ cảnh. - Trả lời các câu hỏi về ý nghĩa truyện, sắp xếp tình tiết truyện. | G6: - Tô các chữ cái trong tổ hợp âm đôi.
A7: 5 | B7: 20 chủ đề: Sức khỏe, Công cụ, Công nghệ,... | C7: - Nhận biết và phát âm được các âm đôi và âm gồm 3 chữ cái. - Ghép các âm vào từ. | D7: - Nghe, hiểu, nắm rõ được tên gọi đồ vật, sự vật, hành động. - Nghe, hiểu và làm theo những yêu cầu để tương tác trong bài học. | E7: - Phát âm rõ ràng các từ vựng và mẫu câu của chủ đề được học. - Nói được câu trong hội thoại và truyện. | F7: - Đọc hiểu, đoán được nghĩa từ vựng, câu trong ngữ cảnh. - Trả lời các câu hỏi về ý nghĩa truyện, sắp xếp tình tiết truyện. | G7: - Tô các tổ hợp phụ âm được cấu tạo bởi 2 - 3 chữ cái.

Sheet MJ 5.0_Level 0_ Game list 07052
G1: Round 0 - GD + PO chuẩn bị tài liệu | Q1: Round 1.1 - Dev (Unity) | Z1: Round 1.1 - BE config data | AG1: Round 1.1 QA test | AQ1: R1.2 - PO + GD + Artist nghiệm thu | AV1: Round 2.1 - Done fix bug | AY1: Round 2.2 Product Team nghiệm thu
I2: Dự kiến | J2: Thực tế | U2: Timeline dự kiến | W2: Timeline thực tế | AD2: Dự kiến | AE2: Thực tế | AJ2: Dự kiến | AM2: Thực tế | AS2: Dự kiến | AT2: Thực tế | AV2: Dự kiến | AW2: Thực tế | AY2: Dự kiến | AZ2: Thực tế
A3: Content type | B3: Activity type | C3: Focus | D3: Course | E3: Game name | F3: Hình thức | G3: Loại data | H3: Video tham khảo | I3: Ngày trả docs | J3: Ngày trả docs | K3: Doc2 cũ | L3: Doc2 mới | M3: Trạng thái doc | N3: Thời gian chuyển dev | O3: Thời gian cần done data | Q3: huongbt_note CR game | R3: PIC dev | S3: STT dev | T3: ETA (days) | U3: Start dev | V3: End dev | W3: Start dev | X3: End dev | Z3: BE Config (1h/ 1 game) | AA3: BE 2 Activity Test | AB3: PO full data | AC3: BE Full Data | AD3: UN Ghép data | AE3: UN Ghép data | AG3: PIC QA | AH3: Start Testcase | AI3: ETA test game (giờ) | AJ3: Start QA | AK3: Done QA | AL3: Ngày chuyển PO nghiệm thu - R1 | AM3: Start QA | AN3: Done QA | AO3: Ngày chuyển PO nghiệm thu - R1 | AQ3: PO_Nghiệm thu game play | AR3: PO_Nghiệm thu game 1 - 2 unit | AS3: PO chuyển Dev | AT3: PO chuyển Dev | AV3: Dev chuyển PO | AW3: Dev chuyển PO | AY3: Product Team nghiệm thu | AZ3: Product Team nghiệm thu
A4: Vocab | B4: Intro | C4: 4 từ | D4: EE.IW01 | E4: Multisensory | F4: Nghe audio + nhìn ảnh/ video | G4: Ảnh/ Video + Audio + Text | H4: Link | K4: Link | L4: Link | M4: Done doc 2 | R4: Tài | S4: Done dev | X4: 21/6 | AG4: Linh Phạm
C5: 4 từ | D5: EE.IV01 | E5: Flashcard | F5: Nghe audio + nhìn ảnh | G5: Ảnh + Audio | H5: Link | K5: Link | L5: Link | M5: Done doc 2 | R5: Thuận | S5: Done dev | X5: 21/6 | AG5: Linh Phạm
A6: Vocab | B6: Guided | C6: 2 từ | D6: EE.IW04 | E6: Tap the balloon | F6: Tap bóng + nghe audio + nhìn ảnh | G6: Ảnh + Audio | H6: Link | K6: Link | L6: Link | M6: Done doc 2 | R6: Thuận | S6: Done dev | U6: 21/6 | V6: 24/6 - chiều | W6: 21/6 | X6: 24/6 - chiều | AG6: Linh Phạm
A7: Vocab | B7: Review | C7: 2 từ | D7: EE.RW08 | E7: Multi-bubble | F7: Nghe audio - chọn ảnh | G7: Ảnh + Audio | H7: Link | K7: Link | L7: Link | M7: Done doc 2 | R7: Nam | S7: Doing | T7: 3 | U7: 24/6 | V7: 26/6 | AG7: Linh Phạm
C8: 2 từ | D8: EE.RV01 | E8: Multiple choice - Image | F8: Cho text - chọn ảnh | G8: Ảnh + Text | H8: Link | K8: Link | L8: Link | M8: Done doc 2 | R8: Thuận | S8: Doing | U8: 24/6 - chiều | V8: 27/6 - sáng | AG8: Linh Phạm
C9: 2 từ | D9: EE.RW02 | E9: Listen and Choose 3 | F9: Nghe audio - chọn ảnh | G9: Ảnh + Audio | H9: Link | K9: Link | AG9: Linh Phạm
A10: SW | B10: Intro | C10: 6 từ | D10: EE.IV04 | E10: Tap 3 options + Flashcard | F10: Tap 3 từ + Flashcard 3 từ | G10: Audio + Text | H10: Link | L10: Link | M10: Done doc 2 | R10: Nam | U10: 27S | AG10: Linh Phạm
A11: SW | B11: Review | C11: 2 từ | D11: BE.RP04 | E11: Listen and Choose 2 | F11: Nghe audio - chọn text | G11: Audio + Text | H11: Link | K11: Link | L11: Link | M11: Done doc 2 | R11: Thuận/ Nam | U11: 27C | AG11: Linh Phạm
A12: Truyện | B12: Input | D12: MJ.ST01 | F12: Đọc truyện | G12: Ảnh/ Video + Audio + Text | L12: Link | M12: Done doc 2 | R12: Tài | U12: 24/6 - chiều | AG12: Linh Phạm
A13: Video | D13: MJ.VD03 | F13: Xem video | G13: Ảnh/ Video | L13: Link | M13: Done doc 2 | AG13: Linh Phạm

Sheet MJ 5.0_Level 0_Flow 070524
A1: Luồng bài học Level 0 - MJ 5.0
A2: Từ vựng chủ đề: 16
A3: Từ SW: 6
A5: Flow 1 | B5: Intro Vocab (4 từ đầu) | C5: Review Vocab (2 từ) | D5: Review Vocab (2 từ) | E5: Intro Vocab (4 từ sau) | F5: Review Vocab (2 từ) | G5: Review Vocab (2 từ) | H5: Intro Vocab (4 từ đầu) | I5: Intro Vocab (4 từ sau) | J5: Intro SW (6 từ) | K5: Review SW (2 đầu)
B6: EE.IW01 - Multisensory | C6: EE.IW04 - Tap the balloon | D6: EE.IW04 - Tap the balloon | E6: EE.IW01 - Multisensory | F6: EE.IW04 - Tap the balloon | G6: EE.IW04 - Tap the balloon | H6: EE.IV01 - Flashcard | I6: EE.IV01 - Flashcard | J6: Tap 3 options + Flashcard | K6: EE.RW09 - Listen and Choose 2
C7: EE.RW08 - Multi-bubble | D7: EE.RW08 - Multi-bubble | F7: EE.RW08 - Multi-bubble | G7: EE.RW08 - Multi-bubble
C8: EE.RV01 - Multiple choice - Image | D8: EE.RV01 - Multiple choice - Image | F8: EE.RV01 - Multiple choice - Image | G8: EE.RV01 - Multiple choice - Image
D9: Anim | G9: Anim | J9: Anim
B12: Intro Vocab (4 từ đầu) | C12: Review Vocab (2 từ) | D12: Review Vocab (2 từ) | E12: Intro Vocab (4 từ sau) | F12: Review Vocab (2 từ) | G12: Review Vocab (2 từ) | H12: Intro Vocab (4 từ đầu) | I12: Intro Vocab (4 từ sau) | J12: Intro SW (6 từ) | K12: Review SW (2 đầu)
B13: Multisensory | C13: Tap bóng + nghe audio + nhìn ảnh | D13: Tap bóng + nghe audio + nhìn ảnh | E13: Multisensory | F13: Tap bóng + nghe audio + nhìn ảnh | G13: Tap bóng + nghe audio + nhìn ảnh | H13: Flashcard | I13: Flashcard | J13: Tap 3 options + Flashcard | K13: Nghe audio - chọn text
C14: Nghe audio - chọn ảnh | D14: Nghe audio - chọn ảnh | F14: Nghe audio - chọn ảnh | G14: Nghe audio - chọn ảnh
C15: Cho text - chọn ảnh | D15: Cho text - chọn ảnh | F15: Cho text - chọn ảnh | G15: Cho text - chọn ảnh
D16: Anim | G16: Anim | J16: Anim
A18: Flow 2 | B18: Play video/ truyện

Sheet MJ 5.0_Level 0_Data 130524
A1: Unit | B1: Level | C1: Topic | D1: Word | E1: Audio từ 1 | F1: Audio từ 2 | G1: Ảnh vẽ (từ) | H1: Ảnh thật 1 (từ) | I1: Ảnh thật 2 (từ) | J1: Video 3s1 | K1: Video 3s2 | L1: Câu 5s1 | M1: Audio 5s1 | N1: Video 5s1 | O1: Ảnh 5s1 | P1: Câu 5s2 | Q1: Audio 5s2 | R1: Video 5s2 | S1: Ảnh 5s2 | T1: Sound effect | U1: Color
A2: 1 | B2: 1 | C2: Animals 1 | D2: cat | E2: https://drive.google.com/file/d/1ob-7ubp1x27Kd3-OzJUxxOQD-Uwg_sB9/view?usp=sharing | F2: https://drive.google.com/file/d/1NEr2tCNWwGxIBqS2qXK47Le3CxHTuuwV/view?usp=sharing | G2: https://drive.google.com/file/d/1AYHmUWaPlG78JSqpkLKQ8iEoKYHI55ta/view?usp=drive_link | H2: https://drive.google.com/file/d/1tVq2TAhw5nLsW3LwWfGT_tVsrBT-FEG3/view?usp=sharing | I2: https://drive.google.com/file/d/1c0wPyk2Ma8NWydrR80N-MopM6ItPeTW9/view?usp=sharing | J2: https://drive.google.com/file/d/1pRbTzxtAn1AqJzrODal1YzlAm8XskFaM/view?usp=sharing | K2: https://drive.google.com/file/d/1FaXjVPHIA-5drGyz3ZOp3MDPD3VLIqNY/view?usp=sharing | L2: That cat is so cute! | M2: https://drive.google.com/file/d/1Yc36I4IJ0TTpunOVvL8PUfSscVgbwS90/view?usp=sharing | O2: https://drive.google.com/file/d/1i4v95OwsFwTjp1Lc17_preFGZFFpOo_5/view?usp=sharing | P2: The cat is jumping. | Q2: https://drive.google.com/file/d/1wiZVwsXmzoGSVu_FGsWlGDw1WBXMo_Qw/view?usp=sharing | S2: https://drive.google.com/file/d/1i7xFlEY_W-pMeJ3iuAqt1KLKfxTz80nn/view?usp=sharing | T2: https://vnmedia2.monkeyuni.net/upload/cms_platform/audio/1f798884bb67c1552f4a6e609e9730ba.mp3
A3: 1 | B3: 1 | C3: Animals 1 | D3: cow | E3: https://drive.google.com/file/d/1_tCnv5E3cNM1Qc1ugF3FesRyhbWGGkIC/view?usp=sharing | F3: https://drive.google.com/file/d/1s9nXdYmVVRftkk_25ECDdNmbjXBJYmuL/view?usp=sharing | G3: https://drive.google.com/file/d/1qtVaJHs2jIeKUVHUmHv8dTFH-uEu9YOh/view?usp=sharing | H3: https://drive.google.com/file/d/1AF-QwJmB3Z5eugqiLervhPwk_HvtmfYh/view?usp=sharing | I3: https://drive.google.com/file/d/14hdeZDUmHOEk5xWI6kUX_QyhX5YuNhhu/view?usp=sharing | J3: https://drive.google.com/file/d/1G79-RjX-oMthENlwqMeqhYqLmfekdJc8/view?usp=sharing | K3: https://drive.google.com/file/d/1UQzBw7QhWrd_wRebrdDxZo6wetM3VKrp/view?usp=sharing | L3: The cows are eating grass. | M3: https://drive.google.com/file/d/1uZoU6txearxHyVx99dhVihSzA7ToY8BH/view?usp=sharing | O3: https://drive.google.com/file/d/1t1JLYWKGO0Ubzeg620s3Wl6f49BvMFcl/view?usp=sharing | P3: The man is feeding the cows. | Q3: https://drive.google.com/file/d/1-VA35z3vKZhW0OlU7J_DdqTamBdDX6mm/view?usp=sharing | S3: https://drive.google.com/file/d/1m6ihLEkFb8bzJty-HV3h8I6tbBHIbDX_/view?usp=sharing | T3: https://vnmedia2.monkeyuni.net/upload/cms_platform/audio/b61bfdf8556d097b67e720893fdd0992.mp3
